<?xml version="1.0" ?>
<!-- =================================================================================== -->
<!-- |    This document was autogenerated by xacro from /home/will/flor_repo/catkin_ws/src/valor_platforms/escher_description/urdf/escher_mesh.xacro | -->
<!-- |    EDITING THIS FILE BY HAND IS NOT RECOMMENDED                                 | -->
<!-- =================================================================================== -->
<robot name="escher" xmlns:xacro="http://www.ros.org/wiki/xacro">
  <material name="$black">
    <color rgba="0 0 0 1.0"/>
  </material>
  <material name="$grey">
    <color rgba="0.15686274509804 0.15686274509804 0.15686274509804 1.0"/>
  </material>
  <material name="$silver">
    <color rgba="0.66274509803922 0.66274509803922 0.66274509803922 1.0"/>
  </material>
  <link name="base_link">
    <origin xyz="0 0 0.9"/>
    <inertial>
      <mass value="0"/>
      <inertia ixx="0" ixy="0" ixz="0" iyy="0" iyz="0" izz="0"/>
    </inertial>
  </link>
  <!-- NOTE: This is not the right way to do this-->
  <link name="x_prismatic_link">
    <origin xyz="0 0 0" />
    <inertial>
      <mass value="0" />
      <inertia ixx="0" ixy="0" ixz="0" iyy="0" iyz="0" izz="0" />
    </inertial>
  </link>
  <link name="y_prismatic_link">
    <origin xyz="0 0 0" />
    <inertial>
      <mass value="0" />
      <inertia ixx="0" ixy="0" ixz="0" iyy="0" iyz="0" izz="0" />
    </inertial>
  </link>
  <link name="z_prismatic_link">
    <origin xyz="0 0 0" />
    <inertial>
      <mass value="0" />
      <inertia ixx="0" ixy="0" ixz="0" iyy="0" iyz="0" izz="0" />
    </inertial>
  </link>
  <link name="roll_revolute_link">
    <origin xyz="0 0 0" />
    <inertial>
      <mass value="0" />
      <inertia ixx="0" ixy="0" ixz="0" iyy="0" iyz="0" izz="0" />
    </inertial>
  </link>
  <link name="pitch_revolute_link">
    <origin xyz="0 0 0" />
    <inertial>
      <mass value="0" />
      <inertia ixx="0" ixy="0" ixz="0" iyy="0" iyz="0" izz="0" />
    </inertial>
  </link>
  <link name="yaw_revolute_link">
    <origin xyz="0 0 0" />
    <inertial>
      <mass value="0" />
      <inertia ixx="0" ixy="0" ixz="0" iyy="0" iyz="0" izz="0" />
    </inertial>
  </link>
  <joint name="x_prismatic_joint" type="prismatic">
    <parent link="base_link"/>
    <child link="x_prismatic_link"/>
    <limit effort="1000.0" lower="-50.0" upper="50.0" velocity="1"/>
    <origin rpy="0 0 0" xyz="0 0 0"/>
    <axis xyz="1 0 0" />
  </joint>
  <joint name="y_prismatic_joint" type="prismatic">
    <parent link="x_prismatic_link"/>
    <child link="y_prismatic_link"/>
    <limit effort="1000.0" lower="-50.0" upper="50.0" velocity="1"/>
    <origin rpy="0 0 0" xyz="0 0 0"/>
    <axis xyz="0 1 0" />
  </joint>
  <joint name="z_prismatic_joint" type="prismatic">
    <parent link="y_prismatic_link"/>
    <child link="z_prismatic_link"/>
    <limit effort="1000.0" lower="-20.0" upper="20.0" velocity="1"/>
    <origin rpy="0 0 0" xyz="0 0 0"/>
    <axis xyz="0 0 1" />
  </joint>
  <joint name="roll_revolute_joint" type="revolute">
    <parent link="z_prismatic_link"/>
    <child link="roll_revolute_link"/>
    <!-- <limit effort="1000.0" lower="-0.5236" higher="0.5236" velocity="1"/> -->
    <!-- <limit effort="1000.0" lower="-0.35" higher="0.35" velocity="1"/> -->
    <limit effort="1000.0" lower="-0.01" higher="0.01" velocity="1"/>
    <origin rpy="0 0 0" xyz="0 0 0"/>
    <axis xyz="1 0 0" />
  </joint>
  <joint name="pitch_revolute_joint" type="revolute">
    <parent link="roll_revolute_link"/>
    <child link="pitch_revolute_link"/>
    <!-- <limit effort="1000.0" lower="-0.5236" higher="0.5236" velocity="1"/> -->
    <!-- <limit effort="1000.0" lower="-0.35" higher="0.35" velocity="1"/> -->
    <limit effort="1000.0" lower="-0.01" higher="0.01" velocity="1"/>
    <origin rpy="0 0 0" xyz="0 0 0"/>
    <axis xyz="0 1 0" />
  </joint>
  <joint name="yaw_revolute_joint" type="continuous">
    <parent link="pitch_revolute_link"/>
    <child link="yaw_revolute_link"/>
    <limit effort="1000.0" velocity="1"/>
    <origin rpy="0 0 0" xyz="0 0 0"/>
    <axis xyz="0 0 1" />
  </joint>


  <link name="torso">
    <origin xyz="0 0 0.9"/>
    <collision name="torso_collision">
      <origin xyz="-0.03035 0 0.155"/>
      <geometry>
        <box size="0.307 0.41 0.26"/>
      </geometry>
    </collision>
    <visual name="torso_visual">
      <origin xyz="0 0 0"/>
      <geometry>
        <mesh filename="package://escher_description/meshes/torso.stl" scale=".001 .001 .001"/>
      </geometry>
      <material name="$silver"/>
    </visual>
    <inertial>
      <origin xyz="-0.027546522 -8.1528e-05 0.133351888"/>
      <mass value="12.662540836356"/>
      <!-- <mass value="26.662540836356"/> -->
      <inertia ixx="0.189594996" ixy="0.000243698" ixz="-0.00084363" iyy="0.165226373" iyz="2.491e-05" izz="0.191129536"/>
    </inertial>
  </link>
  <link name="kvh_link"/>
  <joint name="kvh_joint" type="fixed">
    <origin rpy="0 0 1.5707963267949" xyz="-0.184 0 0.109355"/>
    <axis xyz="0 0 1"/>
    <parent link="torso"/>
    <child link="kvh_link"/>
  </joint>
  <link name="pelvis"/>
  <joint name="pelvis_joint" type="fixed">
    <origin rpy="0 0 0" xyz="0 0 0"/>
    <axis xyz="0 0 1"/>
    <parent link="torso"/>
    <child link="pelvis"/>
  </joint>
  <link name="microstrain_link"/>
  <joint name="microstrain_joint" type="fixed">
    <origin rpy="0 0 0" xyz="-0.206541689 0 0.099894166"/>
    <axis xyz="0 0 1"/>
    <parent link="torso"/>
    <child link="microstrain_link"/>
  </joint>
  <link name="l_thigh">
    <collision name="l_thigh_collision">
      <origin rpy="0 -0.15 0" xyz="-0.0169442 0.032 -0.23"/>
      <geometry>
        <box size="0.28 0.21 0.45"/>
      </geometry>
    </collision>
    <visual name="l_thigh_visual">
      <origin xyz="0 0 0"/>
      <geometry>
        <mesh filename="package://escher_description/meshes/l_thigh.stl" scale=".001 .001 .001"/>
      </geometry>
      <material name="$silver"/>
    </visual>
    <inertial>
      <origin xyz="-0.012893801 0.021195329 -0.207094181"/>
      <mass value="7.1064153123855"/>
      <inertia ixx="0.079832533" ixy="0.005608169" ixz="-0.014464827" iyy="0.090497961" iyz="-0.003214845" izz="0.04397275"/>
    </inertial>
  </link>
  <link name="r_thigh">
    <collision name="r_thigh_collision">
      <origin rpy="0 -0.18 0" xyz="-0.0169442 -0.032 -0.23"/>
      <geometry>
        <box size="0.28 0.21 0.45"/>
      </geometry>
    </collision>
    <visual name="r_thigh_visual">
      <origin xyz="0 0 0"/>
      <geometry>
        <mesh filename="package://escher_description/meshes/r_thigh.stl" scale=".001 .001 .001"/>
      </geometry>
      <material name="$silver"/>
    </visual>
    <inertial>
      <origin xyz="-0.013034539 -0.020824424 -0.207001063"/>
      <mass value="7.0991535785875"/>
      <inertia ixx="0.079523937" ixy="-0.005865006" ixz="-0.014386485" iyy="0.090222577" iyz="0.003378144" izz="0.044391657"/>
    </inertial>
  </link>
  <link name="l_shin">
    <collision name="l_shin_collision">
      <origin rpy="0 0.28 0" xyz="0.0190724 0.0021182 -0.2088892"/>
      <geometry>
        <box size="0.13 0.16 0.4512008"/>
      </geometry>
    </collision>
    <visual name="l_shin_visual">
      <origin xyz="0 0 0"/>
      <geometry>
        <mesh filename="package://escher_description/meshes/l_shin.stl" scale=".001 .001 .001"/>
      </geometry>
      <material name="$silver"/>
    </visual>
    <inertial>
      <origin xyz="0.039203201 0.000387055 -0.154164379"/>
      <mass value="4.891550698374"/>
      <inertia ixx="0.049926224" ixy="-6.1882e-05" ixz="0.008459786" iyy="0.051902624" iyz="-0.000412746" izz="0.017996958"/>
    </inertial>
  </link>
  <link name="r_shin">
    <collision name="r_shin_collision">
      <origin rpy="0 0.28 0" xyz="0.0190724 -0.0021182 -0.2088892"/>
      <geometry>
        <box size="0.13 0.16 0.4512008"/>
      </geometry>
    </collision>
    <visual name="r_shin_visual">
      <origin xyz="0 0 0"/>
      <geometry>
        <mesh filename="package://escher_description/meshes/r_shin.stl" scale=".001 .001 .001"/>
      </geometry>
      <material name="$silver"/>
    </visual>
    <inertial>
      <origin xyz="0.039203093 -0.000281832 -0.15416472"/>
      <mass value="4.8915506176771"/>
      <inertia ixx="0.049926754" ixy="8.0717e-05" ixz="0.008459765" iyy="0.051902784" iyz="0.000377725" izz="0.01799724"/>
    </inertial>
  </link>
  <link name="l_foot">
    <collision name="l_foot_collision">
      <origin xyz="0.025 0 -0.053276"/>
      <geometry>
        <box size="0.25 0.1485 0.05493235"/>
      </geometry>
    </collision>
    <visual name="l_foot_visual">
      <origin xyz="0 0 0"/>
      <geometry>
        <mesh filename="package://escher_description/meshes/l_foot.stl" scale=".001 .001 .001"/>
      </geometry>
      <material name="$silver"/>
    </visual>
    <inertial>
      <origin xyz="-0.003540497 0.00037102999999999 -0.043693482"/>
      <mass value="1.7980371518612"/>
      <inertia ixx="0.003629189" ixy="1.3079e-05" ixz="-0.001366256" iyy="0.007181627" iyz="2.3132e-05" izz="0.007515445"/>
    </inertial>
  </link>
  <link name="r_foot">
    <collision name="r_foot_collision">
      <origin xyz="0.025 0 -0.0533276"/>
      <geometry>
        <box size="0.25 0.1485 0.05493235"/>
      </geometry>
    </collision>
    <visual name="r_foot_visual">
      <origin xyz="0 0 0"/>
      <geometry>
        <mesh filename="package://escher_description/meshes/r_foot.stl" scale=".001 .001 .001"/>
      </geometry>
      <material name="$silver"/>
    </visual>
    <inertial>
      <origin xyz="-0.003252817 -0.00035825099999999 -0.043692447"/>
      <mass value="1.8019124983577"/>
      <inertia ixx="0.003638673" ixy="8.912e-06" ixz="-0.001360529" iyy="0.007191304" iyz="-2.3098e-05" izz="0.007526564"/>
    </inertial>
  </link>
  <link name="l_sole"/>
  <link name="r_sole"/>
  <joint name="l_sole_joint" type="fixed">
    <origin xyz="0.025 0 -0.08"/>
    <parent link="l_foot"/>
    <child link="l_sole"/>
  </joint>
  <joint name="r_sole_joint" type="fixed">
    <origin xyz="0.025 0 -0.08"/>
    <parent link="r_foot"/>
    <child link="r_sole"/>
  </joint>
  <link name="l_hip_yaw_trunnion">
    <!-- Axis = "z", -->
    <inertial>
      <mass value="0.051728795245815"/>
      <inertia ixx="0.0085833333333333" ixy="0" ixz="0" iyy="0.0085833333333333" iyz="0" izz="0.00075"/>
    </inertial>
  </link>
  <link name="r_hip_yaw_trunnion">
    <!-- Axis = "z", -->
    <inertial>
      <mass value="0.051728795245815"/>
      <inertia ixx="0.0085833333333333" ixy="0" ixz="0" iyy="0.0085833333333333" iyz="0" izz="0.00075"/>
    </inertial>
  </link>
  <link name="l_hip_pitch_trunnion">
    <!-- Axis = "y", -->
    <inertial>
      <origin rpy="1.5707963267949 0 0"/>
      <mass value="0.051728795245815"/>
      <inertia ixx="0.0085833333333333" ixy="0" ixz="0" iyy="0.0085833333333333" iyz="0" izz="0.00075"/>
    </inertial>
  </link>
  <link name="r_hip_pitch_trunnion">
    <!-- Axis = "y", -->
    <inertial>
      <origin rpy="1.5707963267949 0 0"/>
      <mass value="0.051728795245815"/>
      <inertia ixx="0.0085833333333333" ixy="0" ixz="0" iyy="0.0085833333333333" iyz="0" izz="0.00075"/>
    </inertial>
  </link>
  <link name="l_ankle_pitch_trunnion">
    <!-- Axis = "y", -->
    <inertial>
      <origin rpy="1.5707963267949 0 0"/>
      <mass value="0.051728795245815"/>
      <inertia ixx="0.0085833333333333" ixy="0" ixz="0" iyy="0.0085833333333333" iyz="0" izz="0.00075"/>
    </inertial>
  </link>
  <link name="r_ankle_pitch_trunnion">
    <!-- Axis = "y", -->
    <inertial>
      <origin rpy="1.5707963267949 0 0"/>
      <mass value="0.051728795245815"/>
      <inertia ixx="0.0085833333333333" ixy="0" ixz="0" iyy="0.0085833333333333" iyz="0" izz="0.00075"/>
    </inertial>
  </link>
  <joint name="base_joint" type="fixed">
    <origin rpy="0 0 0" xyz="0 0 0"/>
    <axis xyz="0 0 1"/>
    <parent link="yaw_revolute_link"/>
    <child link="torso"/>
  </joint>
  <joint name="l_hip_yaw" type="revolute">
    <origin xyz="0 0.1 0"/>
    <parent link="torso"/>
    <child link="l_hip_yaw_trunnion"/>
    <axis xyz="0 0 1"/>
    <limit effort="150" lower="-0.34906585039887" upper="0.78539816339745" velocity="12"/>
    <dynamics damping="1.0" friction="0"/>
  </joint>
  <joint name="r_hip_yaw" type="revolute">
    <origin xyz="0 -0.1 0"/>
    <parent link="torso"/>
    <child link="r_hip_yaw_trunnion"/>
    <axis xyz="0 0 1"/>
    <limit effort="150" lower="-0.78539816339745" upper="0.34906585039887" velocity="12"/>
    <dynamics damping="1.0" friction="0"/>
  </joint>
  <joint name="l_hip_roll" type="revolute">
    <origin xyz="0 0 0"/>
    <parent link="l_hip_yaw_trunnion"/>
    <child link="l_hip_pitch_trunnion"/>
    <axis xyz="1 0 0"/>
    <limit effort="150" lower="-0.5235987755983" upper="0.78539816339745" velocity="12"/>
    <dynamics damping="1.0" friction="0"/>
  </joint>
  <joint name="r_hip_roll" type="revolute">
    <origin xyz="0 0 0"/>
    <parent link="r_hip_yaw_trunnion"/>
    <child link="r_hip_pitch_trunnion"/>
    <axis xyz="1 0 0"/>
    <limit effort="150" lower="-0.78539816339745" upper="0.5235987755983" velocity="12"/>
    <dynamics damping="1.0" friction="0"/>
  </joint>
  <joint name="l_hip_pitch" type="revolute">
    <origin xyz="0 0 0"/>
    <parent link="l_hip_pitch_trunnion"/>
    <child link="l_thigh"/>
    <axis xyz="0 1 0"/>
    <limit effort="200" lower="-2.0943951023932" upper="0.5235987755983" velocity="12"/>
    <dynamics damping="1.0" friction="0"/>
  </joint>
  <joint name="r_hip_pitch" type="revolute">
    <origin xyz="0 0 0"/>
    <parent link="r_hip_pitch_trunnion"/>
    <child link="r_thigh"/>
    <axis xyz="0 1 0"/>
    <limit effort="200" lower="-2.0943951023932" upper="0.5235987755983" velocity="12"/>
    <dynamics damping="1.0" friction="0"/>
  </joint>
  <joint name="l_knee_pitch" type="revolute">
    <origin xyz="0 0 -0.41"/>
    <parent link="l_thigh"/>
    <child link="l_shin"/>
    <axis xyz="0 1 0"/>
    <limit effort="300" lower="0" upper="2.3561944901923" velocity="12"/>
    <dynamics damping="1.0" friction="0"/>
  </joint>
  <joint name="r_knee_pitch" type="revolute">
    <origin xyz="0 0 -0.41"/>
    <parent link="r_thigh"/>
    <child link="r_shin"/>
    <axis xyz="0 1 0"/>
    <limit effort="300" lower="0" upper="2.3561944901923" velocity="12"/>
    <dynamics damping="1.0" friction="0"/>
  </joint>
  <joint name="l_ankle_pitch" type="revolute">
    <origin xyz="0 0 -0.41"/>
    <parent link="l_shin"/>
    <child link="l_ankle_pitch_trunnion"/>
    <axis xyz="0 1 0"/>
    <limit effort="150" lower="-0.95993108859688" upper="0.61086523819802" velocity="12"/>
    <dynamics damping="1.0" friction="0"/>
  </joint>
  <joint name="r_ankle_pitch" type="revolute">
    <origin xyz="0 0 -0.41"/>
    <parent link="r_shin"/>
    <child link="r_ankle_pitch_trunnion"/>
    <axis xyz="0 1 0"/>
    <limit effort="150" lower="-0.95993108859688" upper="0.61086523819802" velocity="12"/>
    <dynamics damping="1.0" friction="0"/>
  </joint>
  <joint name="l_ankle_roll" type="revolute">
    <origin xyz="0 0 0"/>
    <parent link="l_ankle_pitch_trunnion"/>
    <child link="l_foot"/>
    <axis xyz="1 0 0"/>
    <limit effort="150" lower="-0.5235987755983" upper="0.5235987755983" velocity="12"/>
    <dynamics damping="1.0" friction="0"/>
  </joint>
  <joint name="r_ankle_roll" type="revolute">
    <origin xyz="0 0 0"/>
    <parent link="r_ankle_pitch_trunnion"/>
    <child link="r_foot"/>
    <axis xyz="1 0 0"/>
    <limit effort="150" lower="-0.5235987755983" upper="0.5235987755983" velocity="12"/>
    <dynamics damping="1.0" friction="0"/>
  </joint>
  <joint name="waist_yaw" type="revolute">
    <origin xyz="0 0 0.273"/>
    <parent link="torso"/>
    <child link="chest"/>
    <axis xyz="0 0 1"/>
    <limit effort="150" lower="-0.78539816339745" upper="0.78539816339745" velocity="12"/>
    <dynamics damping="1.0" friction="0"/>
  </joint>
  <link name="chest">
    <collision name="chest_collision">
      <origin xyz="-0.02515 0 0.1725"/>
      <geometry>
        <box size="0.24 0.43 0.325"/>
      </geometry>
    </collision>
    <collision name="chest_collision_2">
      <origin xyz="0 0.139 0.485"/>
      <geometry>
        <box size="0.1 0.08 0.33"/>
      </geometry>
    </collision>
    <collision name="chest_collision_3">
      <origin xyz="0 -0.139 0.485"/>
      <geometry>
        <box size="0.1 0.08 0.33"/>
      </geometry>
    </collision>
    <collision name="chest_collision_4">
      <origin xyz="0 0 0.652"/>
      <geometry>
        <box size="0.05 0.22 0.045"/>
      </geometry>
    </collision>
    <visual name="chest_visual">
      <origin xyz="0 0 0"/>
      <geometry>
        <mesh filename="package://escher_description/meshes/chest.stl" scale=".001 .001 .001"/>
      </geometry>
      <material name="$silver"/>
    </visual>
    <inertial>
      <origin xyz="-0.024651386 -0.000572102 0.17357052"/>
      <mass value="15.967544717148"/>
      <!-- <mass value="25.967544717148"/> -->
      <inertia ixx="0.320061097" ixy="-0.001679142" ixz="-0.006857708" iyy="0.258881187" iyz="0.005595512" izz="0.19263458"/>
    </inertial>
  </link>
  <link name="utorso"/>
  <joint name="utorso_joint" type="fixed">
    <origin rpy="0 0 0" xyz="0 0 0"/>
    <axis xyz="0 0 1"/>
    <parent link="chest"/>
    <child link="utorso"/>
  </joint>
  <joint name="head_yaw" type="revolute">
    <origin xyz="0 0 0.365"/>
    <parent link="chest"/>
    <child link="neck"/>
    <axis xyz="0 0 1"/>
    <limit effort="150" lower="-1.5707963267949" upper="1.5707963267949" velocity="12"/>
    <dynamics damping="1.0" friction="0"/>
  </joint>
  <link name="neck">
    <collision name="neck_collision">
      <origin xyz="0 0.003 0.021525"/>
      <geometry>
        <box size="0.0541 0.096 0.05405"/>
      </geometry>
    </collision>
    <visual name="neck_visual">
      <origin xyz="0 0 0"/>
      <geometry>
        <mesh filename="package://escher_description/meshes/neck.stl" scale=".001 .001 .001"/>
      </geometry>
      <material name="$silver"/>
    </visual>
    <inertial>
      <origin xyz="-1e-08 0.000288781 0.025711325"/>
      <mass value="0.4430192306267"/>
      <inertia ixx="0.000347468" ixy="0" ixz="-0" iyy="0.000151286" iyz="-8.157e-06" izz="0.000333572"/>
    </inertial>
  </link>
  <joint name="head_pitch" type="revolute">
    <origin xyz="0 0 0.0286"/>
    <parent link="neck"/>
    <child link="head"/>
    <axis xyz="0 1 0"/>
    <limit effort="150" lower="-0.5235987755983" upper="1.0471975511966" velocity="12"/>
    <dynamics damping="1.0" friction="0"/>
  </joint>
  <link name="head">
    <collision name="head_collision">
      <origin xyz="-0.0142568 0 0.07445"/>
      <geometry>
        <box size="0.155386 0.122 0.2991"/>
      </geometry>
    </collision>
    <visual name="head_visual">
      <origin xyz="0 0 0"/>
      <geometry>
        <mesh filename="package://escher_description/meshes/head.stl" scale=".001 .001 .001"/>
      </geometry>
      <material name="$grey"/>
    </visual>
    <inertial>
      <origin xyz="-0.019043518 1.1808e-05 0.138525812"/>
      <!-- <mass value="1.7856228555403"/> -->
      <mass value="20.7856228555403"/>
      <inertia ixx="0.009989911" ixy="3.49e-06" ixz="0.002192988" iyy="0.010295295" iyz="-8.541e-06" izz="0.003904584"/>
    </inertial>
  </link>
  <!-- MultiSense stereo camera -->
  <gazebo reference="left_camera_frame">
    <sensor name="stereo_camera" type="multicamera">
      <!-- see MultiSenseSLPlugin.h for available modes -->
      <update_rate>30.0</update_rate>
      <camera name="left">
        <!-- Spec sheet says 80deg X 45deg @ 1024x544pix.  Based on feedback
             from teams, we're instead doing 80deg X 80deg @ 800x800pix. -->
        <horizontal_fov>1.3962634</horizontal_fov>
        <image>
          <width>800</width>
          <height>800</height>
          <format>R8G8B8</format>
        </image>
        <clip>
          <near>0.02</near>
          <far>300</far>
        </clip>
        <noise>
          <type>gaussian</type>
          <mean>0.0</mean>
          <stddev>0.007</stddev>
        </noise>
      </camera>
      <camera name="right">
        <pose>0 -0.07 0 0 0 0</pose>
        <!-- Spec sheet says 80deg X 45deg @ 1024x544pix.  Based on feedback
             from teams, we're instead doing 80deg X 80deg @ 800x800pix. -->
        <horizontal_fov>1.3962634</horizontal_fov>
        <image>
          <width>800</width>
          <height>800</height>
          <format>R8G8B8</format>
        </image>
        <clip>
          <near>0.02</near>
          <far>300</far>
        </clip>
        <noise>
          <type>gaussian</type>
          <!-- Noise is sampled independently per pixel on each frame.
               That pixel's noise value is added to each of its color
               channels, which at that point lie in the range [0,1].
               The stddev value of 0.007 is based on experimental data
               from a camera in a Sandia hand pointed at a static scene
               in a couple of different lighting conditions.  -->
          <mean>0.0</mean>
          <stddev>0.007</stddev>
        </noise>
      </camera>
      <plugin filename="libgazebo_ros_multicamera.so" name="stereo_camera_controller">
        <alwaysOn>true</alwaysOn>
        <updateRate>0.0</updateRate>
        <cameraName>multisense</cameraName>
        <imageTopicName>image_color</imageTopicName>
        <cameraInfoTopicName>camera_info</cameraInfoTopicName>
        <frameName>/multisense/left_camera_optical_frame</frameName>
        <!--<rightFrameName>/multisense/right_camera_optical_frame</rightFrameName>-->
        <hackBaseline>0.07</hackBaseline>
        <distortionK1>0.0</distortionK1>
        <distortionK2>0.0</distortionK2>
        <distortionK3>0.0</distortionK3>
        <distortionT1>0.0</distortionT1>
        <distortionT2>0.0</distortionT2>
      </plugin>
    </sensor>
  </gazebo>
  <!-- Multisense params Imported from Official Multisense URDF -->
  <link name="multisense_root"/>
  <joint name="multisense_joint" type="fixed">
    <origin xyz="-0.000435 0 0.18627"/>
    <parent link="head"/>
    <child link="multisense_root"/>
  </joint>
  <joint name="left_camera_joint" type="fixed">
    <origin xyz="0.052 0.035 0.0"/>
    <parent link="multisense_root"/>
    <child link="left_camera_frame"/>
  </joint>
  <link name="left_camera_frame"/>
  <joint name="right_camera_joint" type="fixed">
    <origin xyz="0.052 -0.035 0.0"/>
    <parent link="multisense_root"/>
    <child link="right_camera_frame"/>
  </joint>
  <link name="right_camera_frame"/>
  <joint name="left_camera_optical_joint" type="fixed">
    <origin rpy="-1.57079632679 0.0 -1.57079632679" xyz="0 0 0"/>
    <parent link="left_camera_frame"/>
    <child link="/multisense/left_camera_optical_frame"/>
  </joint>
  <link name="/multisense/left_camera_optical_frame"/>
  <joint name="right_camera_optical_joint" type="fixed">
    <origin rpy="-1.57079632679 0.0 -1.57079632679" xyz="0 0 0"/>
    <parent link="right_camera_frame"/>
    <child link="/multisense/right_camera_optical_frame"/>
  </joint>
  <link name="/multisense/right_camera_optical_frame"/>
  <joint name="accel_joint" type="fixed">
    <origin rpy="0.0 1.57079632679 0.0" xyz="0.047 0.0302 -0.00075"/>
    <parent link="multisense_root"/>
    <child link="accel"/>
  </joint>
  <link name="accel"/>
  <joint name="mag_joint" type="fixed">
    <origin rpy="0.0 1.57079632679 0.0" xyz="0.047 0.0302 -0.00075"/>
    <parent link="multisense_root"/>
    <child link="mag"/>
  </joint>
  <link name="mag"/>
  <joint name="gyro_joint" type="fixed">
    <origin rpy="-1.57079632679 0.0 -1.57079632679" xyz="0.047 0.03880 0.00125"/>
    <parent link="multisense_root"/>
    <child link="gyro"/>
  </joint>
  <link name="gyro"/>
  <!-- Head Lidar -->
  <joint name="head_lidar_roll" type="continuous">
    <origin xyz="0 0 0.089"/>
    <parent link="head"/>
    <child link="head_lidar"/>
    <axis xyz="1 0 0"/>
    <limit effort="150" velocity="12"/>
    <dynamics damping="1.0" friction="0"/>
  </joint>
  <link name="head_lidar">
    <collision name="head_lidar_collision">
      <origin xyz="0 0 0"/>
      <geometry>
        <box size="0.1395 0.06 0.093"/>
      </geometry>
    </collision>
    <visual name="head_lidar_visual">
      <origin xyz="0 0 0"/>
      <geometry>
        <mesh filename="package://escher_description/meshes/head_lidar.stl" scale=".001 .001 .001"/>
      </geometry>
      <material name="$black"/>
    </visual>
    <inertial>
      <origin xyz="0.025363303 -2.21e-06 -3.303568776"/>
      <mass value="0.44909881868181"/>
      <inertia ixx="0.000368817" ixy="5.5e-08" ixz="-8.417e-06" iyy="0.000869352" iyz="-2.1e-08" izz="0.000701866"/>
    </inertial>
  </link>
  <joint name="head_lidar_emitter_joint" type="fixed">
    <origin xyz="0.0495 0 0.02"/>
    <parent link="head_lidar"/>
    <child link="head_lidar_emitter"/>
  </joint>
  <link name="head_hokuyo_frame"/>
  <joint name="head_hokuyo_frame_joint" type="fixed">
    <origin rpy="0 0 0" xyz="0 0 0"/>
    <axis xyz="0 0 1"/>
    <parent link="head_lidar"/>
    <child link="head_hokuyo_frame"/>
  </joint>
  <link name="head_lidar_emitter"/>
  <joint name="head_lidar_receiver_joint" type="fixed">
    <origin xyz="0.0495 0 0.0115"/>
    <parent link="head_lidar"/>
    <child link="head_lidar_receiver"/>
  </joint>
  <link name="head_lidar_receiver"/>
  <joint name="head_lidar_empirical_joint" type="fixed">
    <origin xyz="0 -0.0075 0.0065"/>
    <parent link="head_lidar_emitter"/>
    <child link="head_lidar_empirical"/>
  </joint>
  <link name="head_lidar_empirical"/>
  <!-- hdt arms -->
  <!-- hand included here -->
  <!-- default inertia -->
  <!-- reflect: should be either 1 or -1, and can be multiplied to negate a side -->
  <!--          the left:1, right:-1 mapping is the same as for PR2 (and works with the standard y axis) -->
  <!-- left_only and right_only: will be either 0 or 1, and can be multplied for side-dependent results -->
  <!-- unfortunately, xacro limitations prohibit calculating any of these values from the others, so they must all be passed in -->
  <!-- materials -->
  <material name="l_green">
    <color rgba="0.207843137255 0.36862745098 0.23137254902 1.0"/>
  </material>
  <material name="l_maroon">
    <color rgba="0.294117647059 0.0 0.0 1.0"/>
  </material>
  <material name="l_black">
    <color rgba="0.0 0.0 0.0 1.0"/>
  </material>
  <material name="l_grey">
    <color rgba="0.156862745098 0.156862745098 0.156862745098 1.0"/>
  </material>
  <!-- shoulder -->
  <joint name="l_shoulder_pitch" type="revolute">
    <hdt id="41.0" inertia="0.1" kmax="200" kmin="100"/>
    <axis xyz="-1.0 0 0"/>
    <limit effort="60.0" lower="-3.1416" upper="1.0472" velocity="2.0944"/>
    <origin rpy="0 0 -1.57079" xyz="0 0.1275 0.2804"/>
    <parent link="chest"/>
    <child link="l_shoulder"/>
    <dynamics damping="0.7" friction="0.0"/>
  </joint>
  <transmission name="l_tran1">
    <type>transmission_interface/SimpleTransmission</type>
    <joint name="l_shoulder_pitch">
			</joint>
    <actuator name="l_motor1">
      <hardwareInterface>EffortJointInterface</hardwareInterface>
      <mechanicalReduction>1</mechanicalReduction>
    </actuator>
  </transmission>
  <link name="l_shoulder">
    <collision>
      <origin rpy="0 1.5707963267949 0" xyz="-0.102 -3.7499999999913e-05 0"/>
      <geometry>
        <cylinder radius="0.05"  length="0.2" />
      </geometry>
    </collision>
    <visual>
      <origin rpy="0 0 0" xyz="0 0 0"/>
      <geometry>
        <mesh filename="package://hdt_7dof_description/meshes/shoulder.stl"/>
      </geometry>
      <material name="l_maroon"/>
    </visual>
    <inertial>
      <origin rpy="0 0 0" xyz="-0.04488 0 0"/>
      <mass value="1.00775"/>
      <inertia ixx="0.00064952" ixy="0.0" ixz="0.0" iyy="0.00104342" iyz="0.0" izz="0.00104342"/>
    </inertial>
  </link>
  <gazebo reference="l_shoulder">
    <material>Gazebo/Green</material>
  </gazebo>
  <joint name="l_shoulder_fixed" type="fixed">
    <parent link="l_shoulder"/>
    <child link="l_shoulder_roll_bracket"/>
    <origin rpy="0 0 0" xyz="-0.093 0 0"/>
  </joint>
  <link name="l_shoulder_roll_bracket">
    <!--<collision>-->
      <!--<origin rpy="0 0 0" xyz="0 0 0"/>-->
      <!--<geometry>-->
        <!--<mesh filename="package://hdt_7dof_description/meshes/shoulder_roll_bracket.stl"/>-->
      <!--</geometry>-->
    <!--</collision>-->
    <visual>
      <origin rpy="0 0 0" xyz="0 0 0"/>
      <geometry>
        <mesh filename="package://hdt_7dof_description/meshes/shoulder_roll_bracket.stl"/>
      </geometry>
      <material name="l_black"/>
    </visual>
    <inertial>
      <origin rpy="0 0 0" xyz="-0.04416876 0 0"/>
      <mass value="0.66774822"/>
      <inertia ixx="0.00062987" ixy="0.0" ixz="0.0" iyy="0.00091291" iyz="0.0" izz="0.00110241"/>
    </inertial>
  </link>
  <gazebo reference="l_shoulder_roll_bracket">
    <material>Gazebo/Black</material>
  </gazebo>
  <!-- shoulder roll -->
  <joint name="l_shoulder_roll" type="revolute">
    <hdt id="42.0" inertia="0.1" kmax="200" kmin="100"/>
    <axis xyz="0 1.0 0"/>
    <limit effort="60.0" lower="-0.0" upper="3.1416" velocity="2.0944"/>
    <origin rpy="0 0 0" xyz="-0.07 0 0"/>
    <parent link="l_shoulder_roll_bracket"/>
    <child link="l_shoulder_roll_motor"/>
    <dynamics damping="0.7" friction="0.0"/>
  </joint>
  <transmission name="l_tran2">
    <type>transmission_interface/SimpleTransmission</type>
    <joint name="l_shoulder_roll">
			</joint>
    <actuator name="l_motor2">
      <hardwareInterface>EffortJointInterface</hardwareInterface>
      <mechanicalReduction>1</mechanicalReduction>
    </actuator>
  </transmission>
  <link name="l_shoulder_roll_motor">
    <!--<collision>-->
      <!--<origin rpy="0 0 0" xyz="0 0 0"/>-->
      <!--<geometry>-->
        <!--<mesh filename="package://hdt_7dof_description/meshes/shoulder_roll_motor.stl"/>-->
      <!--</geometry>-->
    <!--</collision>-->
    <visual>
      <origin rpy="0 0 0" xyz="0 0 0.0"/>
      <geometry>
        <mesh filename="package://hdt_7dof_description/meshes/shoulder_roll_motor.stl"/>
      </geometry>
      <material name="l_grey"/>
    </visual>
    <inertial>
      <origin rpy="0 0 0" xyz="0 0 -0.02018105"/>
      <mass value="0.69896"/>
      <inertia ixx="0.00088116" ixy="0.0" ixz="0.0" iyy="0.00094182" iyz="0.0" izz="0.00032992"/>
    </inertial>
  </link>
  <gazebo reference="l_shoulder_roll_motor">
    <material>Gazebo/Grey</material>
  </gazebo>
  <!-- upper arm -->
  <joint name="l_shoulder_yaw" type="revolute">
    <hdt id="43.0" inertia="0.075" kmax="150" kmin="75"/>
    <axis xyz="0 0 1"/>
    <limit effort="60.0" lower="-2.0944" upper="2.0944" velocity="2.0944"/>
    <origin rpy="0 0 0" xyz="0 0 -0.077"/>
    <parent link="l_shoulder_roll_motor"/>
    <child link="l_upper_arm"/>
    <dynamics damping="0.7" friction="0.0"/>
  </joint>
  <transmission name="l_tran3">
    <type>transmission_interface/SimpleTransmission</type>
    <joint name="l_shoulder_yaw">
			</joint>
    <actuator name="l_motor3">
      <hardwareInterface>EffortJointInterface</hardwareInterface>
      <mechanicalReduction>1</mechanicalReduction>
    </actuator>
  </transmission>
  <link name="l_upper_arm">
    <collision>
      <origin rpy="0 0 0" xyz="0 0 -0.14"/>
      <geometry>
        <cylinder radius="0.05" length="0.32" />
      </geometry>
    </collision>
    <visual>
      <origin rpy="0 0 0" xyz="0 0 0.0"/>
      <geometry>
        <mesh filename="package://hdt_7dof_description/meshes/upper_arm.stl"/>
      </geometry>
      <material name="l_maroon"/>
    </visual>
    <inertial>
      <origin rpy="0 0 0" xyz="0 0 -0.08013953"/>
      <mass value="1.3364954742869"/>
      <inertia ixx="0.007190942" ixy="0.0" ixz="0.0" iyy="0.007116565" iyz="-0.000130703" izz="0.000965322"/>
    </inertial>
  </link>
  <gazebo reference="l_upper_arm">
    <material>Gazebo/Green</material>
  </gazebo>
  <joint name="l_upper_arm_fixed" type="fixed">
    <origin rpy="0 0 0" xyz="0 0 -0.1716"/>
    <parent link="l_upper_arm"/>
    <child link="l_elbow_pitch_bracket"/>
  </joint>
  <link name="l_elbow_pitch_bracket">
    <!--<collision>-->
      <!--<origin rpy="0 0 0" xyz="0 0 0"/>-->
      <!--<geometry>-->
        <!--<mesh filename="package://hdt_7dof_description/meshes/elbow_pitch_bracket.stl"/>-->
      <!--</geometry>-->
    <!--</collision>-->
    <visual>
      <origin rpy="0 0 0" xyz="0 0 0.0"/>
      <geometry>
        <mesh filename="package://hdt_7dof_description/meshes/elbow_pitch_bracket.stl"/>
      </geometry>
      <material name="l_black"/>
    </visual>
    <inertial>
      <origin rpy="0 0 0" xyz="0 0 -0.04416876"/>
      <mass value="0.66774822"/>
      <inertia ixx="0.00091291" ixy="0.0" ixz="0.0" iyy="0.00110241" iyz="0.0" izz="0.00062987"/>
    </inertial>
  </link>
  <gazebo reference="l_elbow_pitch_bracket">
    <material>Gazebo/Black</material>
  </gazebo>
  <!-- elbow pitch -->
  <joint name="l_elbow_pitch" type="revolute">
    <hdt id="44.0" inertia="0.075" kmax="150" kmin="75"/>
    <axis xyz="-1.0 0 0"/>
    <limit effort="60.0" lower="-0.5236" upper="3.6651914291881" velocity="2.0944"/>
    <origin rpy="3.1416 0 0" xyz="0 0 -0.07"/>
    <parent link="l_elbow_pitch_bracket"/>
    <child link="l_elbow_pitch_motor"/>
    <dynamics damping="0.7" friction="0.0"/>
  </joint>
  <transmission name="l_tran4">
    <type>transmission_interface/SimpleTransmission</type>
    <joint name="l_elbow_pitch">
			</joint>
    <actuator name="l_motor4">
      <hardwareInterface>EffortJointInterface</hardwareInterface>
      <mechanicalReduction>1</mechanicalReduction>
    </actuator>
  </transmission>
  <link name="l_elbow_pitch_motor">
    <!--<collision>-->
      <!--<origin rpy="0 0 0" xyz="0 0 0"/>-->
      <!--<geometry>-->
        <!--<mesh filename="package://hdt_7dof_description/meshes/elbow_pitch_motor.stl"/>-->
      <!--</geometry>-->
    <!--</collision>-->
    <visual>
      <origin rpy="0 0 0" xyz="0 0 0.0"/>
      <geometry>
        <mesh filename="package://hdt_7dof_description/meshes/elbow_pitch_motor.stl"/>
      </geometry>
      <material name="l_grey"/>
    </visual>
    <inertial>
      <origin rpy="0 0 0" xyz="0 -0.02018105 0"/>
      <mass value="0.69896279"/>
      <inertia ixx="0.00094182" ixy="0.0" ixz="0.0" iyy="0.00032992" iyz="0.0" izz="0.00088116"/>
    </inertial>
  </link>
  <gazebo reference="l_elbow_pitch_motor">
    <material>Gazebo/Grey</material>
  </gazebo>
  <!-- forearm -->
  <joint name="l_elbow_roll" type="revolute">
    <hdt id="45.0" inertia="0.05" kmax="100" kmin="50"/>
    <axis xyz="0 -1 0"/>
    <limit effort="60.0" lower="-2.0944" upper="2.0944" velocity="2.0944"/>
    <origin rpy="0 3.1416 0" xyz="0 -0.077 0"/>
    <parent link="l_elbow_pitch_motor"/>
    <child link="l_forearm"/>
    <dynamics damping="0.7" friction="0.0"/>
  </joint>
  <transmission name="l_tran5">
    <type>transmission_interface/SimpleTransmission</type>
    <joint name="l_elbow_roll">
			</joint>
    <actuator name="l_motor5">
      <hardwareInterface>EffortJointInterface</hardwareInterface>
      <mechanicalReduction>1</mechanicalReduction>
    </actuator>
  </transmission>
  <link name="l_forearm">
    <collision>
      <origin rpy="1.5707963267949 0 0" xyz="0 -0.04 0"/>
      <geometry>
        <cylinder radius="0.05" length="0.1" />
      </geometry>
    </collision>
    <visual>
      <origin rpy="0 0 0" xyz="0 0 0.0"/>
      <geometry>
        <mesh filename="package://hdt_7dof_description/meshes/forearm.stl"/>
      </geometry>
      <material name="l_maroon"/>
    </visual>
    <inertial>
      <origin rpy="0 0 0" xyz="0 -0.04487724 0"/>
      <mass value="1.00775488"/>
      <inertia ixx="0.00104342" ixy="0.0" ixz="0.0" iyy="0.00064952" iyz="0.0" izz="0.00104342"/>
    </inertial>
  </link>
  <gazebo reference="l_forearm">
    <material>Gazebo/Green</material>
  </gazebo>
  <joint name="l_forearm_fixed" type="fixed">
    <origin rpy="0 0 0" xyz="0 -0.0751 0"/>
    <parent link="l_forearm"/>
    <child link="l_wrist_pitch_bracket"/>
  </joint>
  <link name="l_wrist_pitch_bracket">
    <!--<collision>-->
      <!--<origin rpy="0 0 0" xyz="0 0 0"/>-->
      <!--<geometry>-->
        <!--<mesh filename="package://hdt_7dof_description/meshes/wrist_pitch_bracket.stl"/>-->
      <!--</geometry>-->
    <!--</collision>-->
    <visual>
      <origin rpy="0 0 0" xyz="0 0 0.0"/>
      <geometry>
        <mesh filename="package://hdt_7dof_description/meshes/wrist_pitch_bracket.stl"/>
      </geometry>
      <material name="l_black"/>
    </visual>
    <inertial>
      <origin rpy="0 0 0" xyz="0 -0.04112 0"/>
      <mass value="0.50058"/>
      <inertia ixx="0.000580228" ixy="0.0" ixz="0.0" iyy="0.000541503" iyz="0.0" izz="0.000750977"/>
    </inertial>
  </link>
  <gazebo reference="l_wrist_pitch_bracket">
    <material>Gazebo/Black</material>
  </gazebo>
  <!-- wrist pitch -->
  <joint name="l_wrist_pitch" type="revolute">
    <hdt id="46.0" inertia="0.05" kmax="100" kmin="50"/>
    <axis xyz="1 0 0"/>
    <limit effort="60.0" lower="-1.5708" upper="1.5708" velocity="2.0944"/>
    <origin rpy="0 0 0" xyz="0 -0.055 0"/>
    <parent link="l_wrist_pitch_bracket"/>
    <child link="l_wrist_motors"/>
    <dynamics damping="0.7" friction="0.0"/>
  </joint>
  <transmission name="l_tran6">
    <type>transmission_interface/SimpleTransmission</type>
    <joint name="l_wrist_pitch">
			</joint>
    <actuator name="l_motor6">
      <hardwareInterface>EffortJointInterface</hardwareInterface>
      <mechanicalReduction>1</mechanicalReduction>
    </actuator>
  </transmission>
  <link name="l_wrist_motors">
    <collision>
      <origin rpy="0 1.5707963267949 0" xyz="0 0 0"/>
      <geometry>
        <cylinder radius="0.05" length="0.08" />
      </geometry>
    </collision>
    <visual>
      <origin rpy="0 0 0" xyz="0 0 0.0"/>
      <geometry>
        <mesh filename="package://hdt_7dof_description/meshes/wrist_motors.stl"/>
      </geometry>
      <material name="l_grey"/>
    </visual>
    <inertial>
      <origin rpy="0 0 0" xyz="0 -0.03855 0"/>
      <mass value="0.99934"/>
      <inertia ixx="0.001905243" ixy="0.0" ixz="0.0" iyy="0.000474765" iyz="0.0" izz="0.001905243"/>
    </inertial>
  </link>
  <gazebo reference="l_wrist_motors">
    <material>Gazebo/Grey</material>
  </gazebo>
  <!-- wrist yaw -->
  <joint name="l_wrist_yaw" type="revolute">
    <hdt id="47.0" inertia="0.05" kmax="100" kmin="50"/>
    <axis xyz="0 0 1"/>
    <!-- <limit effort="60.0" lower="-1.5708" upper="1.5708" velocity="2.0944"/> -->
    <limit effort="60.0" lower="0" upper="1.5708" velocity="2.0944"/>
    <origin rpy="0 0 0" xyz="0 -0.0741 0"/>
    <parent link="l_wrist_motors"/>
    <child link="l_wrist_yaw_bracket"/>
    <dynamics damping="0.7" friction="0.0"/>
  </joint>
  <transmission name="l_tran7">
    <type>transmission_interface/SimpleTransmission</type>
    <joint name="l_wrist_yaw">
			</joint>
    <actuator name="l_motor7">
      <hardwareInterface>EffortJointInterface</hardwareInterface>
      <mechanicalReduction>1</mechanicalReduction>
    </actuator>
  </transmission>
  <link name="l_wrist_yaw_bracket">
    <collision>
      <origin rpy="0 0 0" xyz="0 0 0"/>
      <geometry>
        <cylinder radius="0.05" length="0.08" />
      </geometry>
    </collision>
    <visual>
      <origin rpy="0 0 0" xyz="0 0 0.0"/>
      <geometry>
        <mesh filename="package://hdt_7dof_description/meshes/wrist_yaw_bracket.stl"/>
      </geometry>
      <material name="l_black"/>
    </visual>
    <inertial>
      <origin rpy="0 0 0" xyz="0 -0.01177 0"/>
      <mass value="0.47608"/>
      <inertia ixx="0.000705091" ixy="0.0" ixz="0.0" iyy="0.000537081" iyz="0.0" izz="0.000534342"/>
    </inertial>
  </link>
  <gazebo reference="l_wrist_yaw_bracket">
    <material>Gazebo/Black</material>
  </gazebo>
  <!-- palm -->
  <joint name="l_palm" type="fixed">
    <origin rpy="0 0 0" xyz="0 -0.1876 0"/>
    <parent link="l_wrist_yaw_bracket"/>
    <child link="l_hand"/>
  </joint>
  <link name="l_palm">
    <collision>
      <origin rpy="0 0 0" xyz="0 -0.068 0.004"/>
      <geometry>
        <box size="0.071 0.18 0.105"/>
      </geometry>
    </collision>
    <visual>
      <origin rpy="0 0 0" xyz="0 0 0.0"/>
      <geometry>
        <mesh filename="package://hdt_7dof_description/meshes/palm.stl"/>
      </geometry>
      <material name="l_black"/>
    </visual>
    <inertial>
      <origin rpy="0 0 0" xyz="0 -0.08326 -0.00539"/>
      <!-- <mass value="0.56756"/> -->
      <!-- <mass value="0.96756"/> -->
      <mass value="5.56756"/>
      <inertia ixx="0.001727803" ixy="0.000001205" ixz="0.0" iyy="0.000549457" iyz="-0.000101997" izz="0.001418031"/>
    </inertial>
  </link>
  <gazebo reference="l_palm">
    <material>Gazebo/Black</material>
  </gazebo>
  <!-- gripper frame -->
  <joint name="l_gripper_frame_joint" type="fixed">
    <origin rpy="0 0 -1.57079" xyz="0 0 0"/>
    <parent link="l_palm"/>
    <child link="l_gripper_frame"/>
  </joint>
  <link name="l_gripper_frame"/>
  <!-- Hacked in joint to match ViGIR frames -->
  <joint name="l_vigir_joint" type="fixed">
    <origin rpy="0 0 0" xyz="0 0.13 0"/>
    <parent link="l_hand"/>
    <child link="l_palm"/>
  </joint>
  <link name="l_hand"/>
  <!-- thumb base -->
  <joint name="l_thumb_roll" type="revolute">
    <hdt id="50.0" inertia="0.01" kmax="20" kmin="5"/>
    <axis xyz="0 -1 0"/>
    <limit effort="4.0" lower="-1.5708" upper="1.5708" velocity="4.1888"/>
    <origin rpy="0 0 0" xyz="0 -0.05039 0.01529"/>
    <parent link="l_palm"/>
    <child link="l_thumb_base"/>
    <dynamics damping="0.7" friction="0.0"/>
  </joint>
  <transmission name="l_tran10">
    <type>transmission_interface/SimpleTransmission</type>
    <joint name="l_thumb_roll">
            </joint>
    <actuator name="l_motor10">
      <hardwareInterface>EffortJointInterface</hardwareInterface>
      <mechanicalReduction>1</mechanicalReduction>
    </actuator>
  </transmission>
  <link name="l_thumb_base">
    <!--<collision>-->
      <!--<origin rpy="0 0 0" xyz="0 0 0"/>-->
      <!--<geometry>-->
        <!--<mesh filename="package://hdt_7dof_description/meshes/thumb_base.stl"/>-->
      <!--</geometry>-->
    <!--</collision>-->
    <visual>
      <origin rpy="0 0 0" xyz="0 0 0"/>
      <geometry>
        <mesh filename="package://hdt_7dof_description/meshes/thumb_base.stl"/>
      </geometry>
      <material name="l_grey"/>
    </visual>
    <inertial>
      <origin rpy="0 0 0" xyz="0 -0.02653 0.02207"/>
      <mass value="0.08562"/>
      <inertia ixx="0.0000315" ixy="0.0" ixz="0.0" iyy="0.000034299" iyz="0.0" izz="0.000022344"/>
    </inertial>
  </link>
  <gazebo reference="l_thumb_base">
    <material>Gazebo/Grey</material>
  </gazebo>
  <!-- thumb prox -->
  <joint name="l_thumb_pitch" type="revolute">
    <hdt id="51.0" inertia="0.01" kmax="20" kmin="5"/>
    <axis xyz="1 0 0"/>
    <limit effort="4.0" lower="-0.7854" upper="1.5708" velocity="4.1888"/>
    <origin rpy="0 0 0" xyz="0.00214 -0.030093 0.05703"/>
    <parent link="l_thumb_base"/>
    <child link="l_thumb_prox"/>
    <dynamics damping="0.7" friction="0.0"/>
  </joint>
  <transmission name="l_tran11">
    <type>transmission_interface/SimpleTransmission</type>
    <joint name="l_thumb_pitch">
            </joint>
    <actuator name="l_motor11">
      <hardwareInterface>EffortJointInterface</hardwareInterface>
      <mechanicalReduction>1</mechanicalReduction>
    </actuator>
  </transmission>
  <link name="l_thumb_prox">
    <collision>
      <origin rpy="0 0 0" xyz="0 0 0.054"/>
      <geometry>
        <cylinder radius="0.025" length="0.1" />
      </geometry>
    </collision>
    <visual>
      <origin rpy="0 0 0" xyz="0 0 0"/>
      <geometry>
        <mesh filename="package://hdt_7dof_description/meshes/thumb_prox.stl"/>
      </geometry>
      <material name="l_grey"/>
    </visual>
    <inertial>
      <mass value="0.025"/>
      <inertia ixx="0.0005" ixy="0.0" ixz="0.0" iyy="0.0005" iyz="0.0" izz="0.0005"/>
    </inertial>
  </link>
  <gazebo reference="l_thumb_prox">
    <material>Gazebo/Grey</material>
  </gazebo>
  <!-- thumb med -->
  <joint name="l_thumb_med" type="fixed">
    <origin rpy="0 0 0" xyz="0 0.00285 0.04341"/>
    <parent link="l_thumb_prox"/>
    <child link="l_thumb_med"/>
  </joint>
  <link name="l_thumb_med">
    <!--<collision>-->
      <!--<origin rpy="0 0 0" xyz="0 0 0"/>-->
      <!--<geometry>-->
        <!--<mesh filename="package://hdt_7dof_description/meshes/thumb_med.stl"/>-->
      <!--</geometry>-->
    <!--</collision>-->
    <visual>
      <origin rpy="0 0 0" xyz="0 0 0"/>
      <geometry>
        <mesh filename="package://hdt_7dof_description/meshes/thumb_med.stl"/>
      </geometry>
      <material name="l_black"/>
    </visual>
    <inertial>
      <origin rpy="0 0 0" xyz="0 -0.00353 0.01162"/>
      <mass value="0.0085"/>
      <inertia ixx="0.000001099" ixy="0.0" ixz="0.0" iyy="0.000001639" iyz="0.000000096" izz="0.000000981"/>
    </inertial>
  </link>
  <gazebo reference="l_thumb_med">
    <material>Gazebo/Black</material>
  </gazebo>
  <!-- thumb dist -->
  <joint name="l_thumb_dist" type="fixed">
    <origin rpy="0 0 0" xyz="0 -0.0009 0.02769"/>
    <parent link="l_thumb_med"/>
    <child link="l_thumb_dist"/>
  </joint>
  <link name="l_thumb_dist">
    <!--<collision>-->
      <!--<origin rpy="0 0 0" xyz="0 0 0"/>-->
      <!--<geometry>-->
        <!--<mesh filename="package://hdt_7dof_description/meshes/thumb_dist.stl"/>-->
      <!--</geometry>-->
    <!--</collision>-->
    <visual>
      <origin rpy="0 0 0" xyz="0 0 0"/>
      <geometry>
        <mesh filename="package://hdt_7dof_description/meshes/thumb_dist.stl"/>
      </geometry>
      <material name="l_grey"/>
    </visual>
    <inertial>
      <origin rpy="0 0 0" xyz="0 -0.00131 0.01323"/>
      <mass value="0.0092"/>
      <inertia ixx="0.00000066" ixy="0.0" ixz="0.0" iyy="0.000000837" iyz="0.0" izz="0.000000695"/>
    </inertial>
  </link>
  <gazebo reference="l_thumb_dist">
    <material>Gazebo/Grey</material>
  </gazebo>
  <!-- index prox -->
  <joint name="l_index_yaw" type="revolute">
    <hdt id="52.0" inertia="0.01" kmax="20" kmin="5"/>
    <axis xyz="0 0 -1.0"/>
    <limit effort="4.0" lower="-1.5708" upper="0.7854" velocity="4.1888"/>
    <origin rpy="0 3.1416 0" xyz="0 -0.163498 0.027"/>
    <parent link="l_palm"/>
    <child link="l_index_prox"/>
    <dynamics damping="0.7" friction="0.0"/>
  </joint>
  <transmission name="l_tran12">
    <type>transmission_interface/SimpleTransmission</type>
    <joint name="l_index_yaw">
            </joint>
    <actuator name="l_motor12">
      <hardwareInterface>EffortJointInterface</hardwareInterface>
      <mechanicalReduction>1</mechanicalReduction>
    </actuator>
  </transmission>
  <link name="l_index_prox">
    <collision>
      <origin rpy="-1.5707963267949 0 0" xyz="0 -0.043 0"/>
      <geometry>
        <cylinder radius="0.025" length="0.1" />
      </geometry>
    </collision>
    <visual>
      <origin rpy="0 0 0" xyz="0 0 0"/>
      <geometry>
        <mesh filename="package://hdt_7dof_description/meshes/finger_prox_right.stl"/>
      </geometry>
      <material name="l_grey"/>
    </visual>
    <inertial>
      <mass value="0.025"/>
      <inertia ixx="0.0005" ixy="0.0" ixz="0.0" iyy="0.0005" iyz="0.0" izz="0.0005"/>
    </inertial>
  </link>
  <gazebo reference="l_index_prox">
    <material>Gazebo/Grey</material>
  </gazebo>
  <!-- index med -->
  <joint name="l_index_med" type="fixed">
    <origin rpy="0 0 0" xyz="-0.00285 -0.04341 0"/>
    <parent link="l_index_prox"/>
    <child link="l_index_med"/>
  </joint>
  <link name="l_index_med">
    <!--<collision>-->
      <!--<origin rpy="0 0 0" xyz="0 0 0"/>-->
      <!--<geometry>-->
        <!--<mesh filename="package://hdt_7dof_description/meshes/finger_med_right.stl"/>-->
      <!--</geometry>-->
    <!--</collision>-->
    <visual>
      <origin rpy="0 0 0" xyz="0 0 0"/>
      <geometry>
        <mesh filename="package://hdt_7dof_description/meshes/finger_med_right.stl"/>
      </geometry>
      <material name="l_black"/>
    </visual>
    <inertial>
      <origin rpy="0 0 0" xyz="0.00353 -0.01162 0"/>
      <mass value="0.0085"/>
      <inertia ixx="0.000001639" ixy="0.000000096" ixz="0.0" iyy="0.000000981" iyz="0.0" izz="0.000001099"/>
    </inertial>
  </link>
  <gazebo reference="l_index_med">
    <material>Gazebo/Black</material>
  </gazebo>
  <!-- index dist -->
  <joint name="l_index_dist" type="fixed">
    <origin rpy="0 0 0" xyz="0.0009 -0.02769 0"/>
    <parent link="l_index_med"/>
    <child link="l_index_dist"/>
  </joint>
  <link name="l_index_dist">
    <!--<collision>-->
      <!--<origin rpy="0 0 0" xyz="0 0 0"/>-->
      <!--<geometry>-->
        <!--<mesh filename="package://hdt_7dof_description/meshes/finger_dist_right.stl"/>-->
      <!--</geometry>-->
    <!--</collision>-->
    <visual>
      <origin rpy="0 0 0" xyz="0 0 0"/>
      <geometry>
        <mesh filename="package://hdt_7dof_description/meshes/finger_dist_right.stl"/>
      </geometry>
      <material name="l_grey"/>
    </visual>
    <inertial>
      <origin rpy="0 0 0" xyz="0.00131 -0.01323 0"/>
      <mass value="0.0092"/>
      <inertia ixx="0.000000837" ixy="0.0" ixz="0.0" iyy="0.000000695" iyz="0.0" izz="0.00000066"/>
    </inertial>
  </link>
  <gazebo reference="l_index_dist">
    <material>Gazebo/Grey</material>
  </gazebo>
  <!-- ring prox -->
  <joint name="l_ring_yaw" type="revolute">
    <hdt id="53.0" inertia="0.01" kmax="20" kmin="5"/>
    <axis xyz="0 0 -1.0"/>
    <limit effort="4.0" lower="-1.5708" upper="0.7854" velocity="4.1888"/>
    <origin rpy="0 3.1416 0" xyz="0 -0.163498 -0.027"/>
    <parent link="l_palm"/>
    <child link="l_ring_prox"/>
    <dynamics damping="0.7" friction="0.0"/>
  </joint>
  <transmission name="l_tran13">
    <type>transmission_interface/SimpleTransmission</type>
    <joint name="l_ring_yaw">
            </joint>
    <actuator name="l_motor13">
      <hardwareInterface>EffortJointInterface</hardwareInterface>
      <mechanicalReduction>1</mechanicalReduction>
    </actuator>
  </transmission>
  <link name="l_ring_prox">
    <collision>
      <origin rpy="-1.5707963267949 0 0" xyz="0 -0.043 0"/>
      <geometry>
        <cylinder radius="0.025" length="0.1" />
      </geometry>
    </collision>
    <visual>
      <origin rpy="0 0 0" xyz="0 0 0"/>
      <geometry>
        <mesh filename="package://hdt_7dof_description/meshes/finger_prox_right.stl"/>
      </geometry>
      <material name="l_grey"/>
    </visual>
    <inertial>
      <mass value="0.025"/>
      <inertia ixx="0.0005" ixy="0.0" ixz="0.0" iyy="0.0005" iyz="0.0" izz="0.0005"/>
    </inertial>
  </link>
  <gazebo reference="l_ring_prox">
    <material>Gazebo/Grey</material>
  </gazebo>
  <!-- ring med -->
  <joint name="l_ring_med" type="fixed">
    <origin rpy="0 0 0" xyz="-0.00285 -0.04341 0"/>
    <parent link="l_ring_prox"/>
    <child link="l_ring_med"/>
  </joint>
  <link name="l_ring_med">
    <!--<collision>-->
      <!--<origin rpy="0 0 0" xyz="0 0 0"/>-->
      <!--<geometry>-->
        <!--<mesh filename="package://hdt_7dof_description/meshes/finger_med_right.stl"/>-->
      <!--</geometry>-->
    <!--</collision>-->
    <visual>
      <origin rpy="0 0 0" xyz="0 0 0"/>
      <geometry>
        <mesh filename="package://hdt_7dof_description/meshes/finger_med_right.stl"/>
      </geometry>
      <material name="l_black"/>
    </visual>
    <inertial>
      <origin rpy="0 0 0" xyz="0.00353 -0.01162 0"/>
      <mass value="0.0085"/>
      <inertia ixx="0.000001639" ixy="0.000000096" ixz="0.0" iyy="0.000000981" iyz="0.0" izz="0.000001099"/>
    </inertial>
  </link>
  <gazebo reference="l_ring_med">
    <material>Gazebo/Black</material>
  </gazebo>
  <!-- ring dist -->
  <joint name="l_ring_dist" type="fixed">
    <origin rpy="0 0 0" xyz="0.0009 -0.02769 0"/>
    <parent link="l_ring_med"/>
    <child link="l_ring_dist"/>
  </joint>
  <link name="l_ring_dist">
    <!--<collision>-->
      <!--<origin rpy="0 0 0" xyz="0 0 0"/>-->
      <!--<geometry>-->
        <!--<mesh filename="package://hdt_7dof_description/meshes/finger_dist_right.stl"/>-->
      <!--</geometry>-->
    <!--</collision>-->
    <visual>
      <origin rpy="0 0 0" xyz="0 0 0"/>
      <geometry>
        <mesh filename="package://hdt_7dof_description/meshes/finger_dist_right.stl"/>
      </geometry>
      <material name="l_grey"/>
    </visual>
    <inertial>
      <origin rpy="0 0 0" xyz="0.00131 -0.01323 0"/>
      <mass value="0.0092"/>
      <inertia ixx="0.000000837" ixy="0.0" ixz="0.0" iyy="0.000000695" iyz="0.0" izz="0.00000066"/>
    </inertial>
  </link>
  <gazebo reference="l_ring_dist">
    <material>Gazebo/Grey</material>
  </gazebo>
  <!-- materials -->
  <material name="r_green">
    <color rgba="0.207843137255 0.36862745098 0.23137254902 1.0"/>
  </material>
  <material name="r_maroon">
    <color rgba="0.294117647059 0.0 0.0 1.0"/>
  </material>
  <material name="r_black">
    <color rgba="0.0 0.0 0.0 1.0"/>
  </material>
  <material name="r_grey">
    <color rgba="0.156862745098 0.156862745098 0.156862745098 1.0"/>
  </material>
  <!-- shoulder -->
  <joint name="r_shoulder_pitch" type="revolute">
    <hdt id="1.0" inertia="0.1" kmax="200" kmin="100"/>
    <axis xyz="1.0 0 0"/>
    <limit effort="60.0" lower="-3.1416" upper="1.0472" velocity="2.0944"/>
    <origin rpy="0 0 1.57079" xyz="0 -0.1275 0.2804"/>
    <parent link="chest"/>
    <child link="r_shoulder"/>
    <dynamics damping="0.7" friction="0.0"/>
  </joint>
  <transmission name="r_tran1">
    <type>transmission_interface/SimpleTransmission</type>
    <joint name="r_shoulder_pitch">
			</joint>
    <actuator name="r_motor1">
      <hardwareInterface>EffortJointInterface</hardwareInterface>
      <mechanicalReduction>1</mechanicalReduction>
    </actuator>
  </transmission>
  <link name="r_shoulder">
    <collision>
      <origin rpy="0 1.5707963267949 0" xyz="-0.102 -3.7499999999913e-05 0"/>
      <geometry>
        <cylinder radius="0.05"  length="0.2" />
      </geometry>
    </collision>
    <visual>
      <origin rpy="0 0 0" xyz="0 0 0"/>
      <geometry>
        <mesh filename="package://hdt_7dof_description/meshes/shoulder.stl"/>
      </geometry>
      <material name="r_maroon"/>
    </visual>
    <inertial>
      <origin rpy="0 0 0" xyz="-0.04488 0 0"/>
      <mass value="1.00775"/>
      <inertia ixx="0.00064952" ixy="0.0" ixz="0.0" iyy="0.00104342" iyz="0.0" izz="0.00104342"/>
    </inertial>
  </link>
  <gazebo reference="r_shoulder">
    <material>Gazebo/Green</material>
  </gazebo>
  <joint name="r_shoulder_fixed" type="fixed">
    <parent link="r_shoulder"/>
    <child link="r_shoulder_roll_bracket"/>
    <origin rpy="0 0 0" xyz="-0.093 0 0"/>
  </joint>
  <link name="r_shoulder_roll_bracket">
    <!--<collision>-->
      <!--<origin rpy="0 0 0" xyz="0 0 0"/>-->
      <!--<geometry>-->
        <!--<mesh filename="package://hdt_7dof_description/meshes/shoulder_roll_bracket.stl"/>-->
      <!--</geometry>-->
    <!--</collision>-->
    <visual>
      <origin rpy="0 0 0" xyz="0 0 0"/>
      <geometry>
        <mesh filename="package://hdt_7dof_description/meshes/shoulder_roll_bracket.stl"/>
      </geometry>
      <material name="r_black"/>
    </visual>
    <inertial>
      <origin rpy="0 0 0" xyz="-0.04416876 0 0"/>
      <mass value="0.66774822"/>
      <inertia ixx="0.00062987" ixy="0.0" ixz="0.0" iyy="0.00091291" iyz="0.0" izz="0.00110241"/>
    </inertial>
  </link>
  <gazebo reference="r_shoulder_roll_bracket">
    <material>Gazebo/Black</material>
  </gazebo>
  <!-- shoulder roll -->
  <joint name="r_shoulder_roll" type="revolute">
    <hdt id="2.0" inertia="0.1" kmax="200" kmin="100"/>
    <axis xyz="0 -1.0 0"/>
    <limit effort="60.0" lower="-3.1416" upper="0.0" velocity="2.0944"/>
    <origin rpy="0 0 0" xyz="-0.07 0 0"/>
    <parent link="r_shoulder_roll_bracket"/>
    <child link="r_shoulder_roll_motor"/>
    <dynamics damping="0.7" friction="0.0"/>
  </joint>
  <transmission name="r_tran2">
    <type>transmission_interface/SimpleTransmission</type>
    <joint name="r_shoulder_roll">
			</joint>
    <actuator name="r_motor2">
      <hardwareInterface>EffortJointInterface</hardwareInterface>
      <mechanicalReduction>1</mechanicalReduction>
    </actuator>
  </transmission>
  <link name="r_shoulder_roll_motor">
    <!--<collision>-->
      <!--<origin rpy="0 0 0" xyz="0 0 0"/>-->
      <!--<geometry>-->
        <!--<mesh filename="package://hdt_7dof_description/meshes/shoulder_roll_motor.stl"/>-->
      <!--</geometry>-->
    <!--</collision>-->
    <visual>
      <origin rpy="0 0 0" xyz="0 0 0.0"/>
      <geometry>
        <mesh filename="package://hdt_7dof_description/meshes/shoulder_roll_motor.stl"/>
      </geometry>
      <material name="r_grey"/>
    </visual>
    <inertial>
      <origin rpy="0 0 0" xyz="0 0 -0.02018105"/>
      <mass value="0.69896"/>
      <inertia ixx="0.00088116" ixy="0.0" ixz="0.0" iyy="0.00094182" iyz="0.0" izz="0.00032992"/>
    </inertial>
  </link>
  <gazebo reference="r_shoulder_roll_motor">
    <material>Gazebo/Grey</material>
  </gazebo>
  <!-- upper arm -->
  <joint name="r_shoulder_yaw" type="revolute">
    <hdt id="3.0" inertia="0.075" kmax="150" kmin="75"/>
    <axis xyz="0 0 1"/>
    <limit effort="60.0" lower="-2.0944" upper="2.0944" velocity="2.0944"/>
    <origin rpy="0 0 0" xyz="0 0 -0.077"/>
    <parent link="r_shoulder_roll_motor"/>
    <child link="r_upper_arm"/>
    <dynamics damping="0.7" friction="0.0"/>
  </joint>
  <transmission name="r_tran3">
    <type>transmission_interface/SimpleTransmission</type>
    <joint name="r_shoulder_yaw">
			</joint>
    <actuator name="r_motor3">
      <hardwareInterface>EffortJointInterface</hardwareInterface>
      <mechanicalReduction>1</mechanicalReduction>
    </actuator>
  </transmission>
  <link name="r_upper_arm">
    <collision>
      <origin rpy="0 0 0" xyz="0 0 -0.14"/>
      <geometry>
        <cylinder radius="0.05" length="0.32" />
      </geometry>
    </collision>
    <visual>
      <origin rpy="0 0 0" xyz="0 0 0.0"/>
      <geometry>
        <mesh filename="package://hdt_7dof_description/meshes/upper_arm.stl"/>
      </geometry>
      <material name="r_maroon"/>
    </visual>
    <inertial>
      <origin rpy="0 0 0" xyz="0 0 -0.08013953"/>
      <mass value="1.3364954742869"/>
      <inertia ixx="0.007190942" ixy="0.0" ixz="0.0" iyy="0.007116565" iyz="0.000130703" izz="0.000965322"/>
    </inertial>
  </link>
  <gazebo reference="r_upper_arm">
    <material>Gazebo/Green</material>
  </gazebo>
  <joint name="r_upper_arm_fixed" type="fixed">
    <origin rpy="0 0 0" xyz="0 0 -0.1716"/>
    <parent link="r_upper_arm"/>
    <child link="r_elbow_pitch_bracket"/>
  </joint>
  <link name="r_elbow_pitch_bracket">
    <!--<collision>-->
      <!--<origin rpy="0 0 0" xyz="0 0 0"/>-->
      <!--<geometry>-->
        <!--<mesh filename="package://hdt_7dof_description/meshes/elbow_pitch_bracket.stl"/>-->
      <!--</geometry>-->
    <!--</collision>-->
    <visual>
      <origin rpy="0 0 0" xyz="0 0 0.0"/>
      <geometry>
        <mesh filename="package://hdt_7dof_description/meshes/elbow_pitch_bracket.stl"/>
      </geometry>
      <material name="r_black"/>
    </visual>
    <inertial>
      <origin rpy="0 0 0" xyz="0 0 -0.04416876"/>
      <mass value="0.66774822"/>
      <inertia ixx="0.00091291" ixy="0.0" ixz="0.0" iyy="0.00110241" iyz="0.0" izz="0.00062987"/>
    </inertial>
  </link>
  <gazebo reference="r_elbow_pitch_bracket">
    <material>Gazebo/Black</material>
  </gazebo>
  <!-- elbow pitch -->
  <joint name="r_elbow_pitch" type="revolute">
    <hdt id="4.0" inertia="0.075" kmax="150" kmin="75"/>
    <axis xyz="1.0 0 0"/>
    <limit effort="60.0" lower="-0.5236" upper="3.6651914291881" velocity="2.0944"/>
    <origin rpy="0.0 0 0" xyz="0 0 -0.07"/>
    <parent link="r_elbow_pitch_bracket"/>
    <child link="r_elbow_pitch_motor"/>
    <dynamics damping="0.7" friction="0.0"/>
  </joint>
  <transmission name="r_tran4">
    <type>transmission_interface/SimpleTransmission</type>
    <joint name="r_elbow_pitch">
			</joint>
    <actuator name="r_motor4">
      <hardwareInterface>EffortJointInterface</hardwareInterface>
      <mechanicalReduction>1</mechanicalReduction>
    </actuator>
  </transmission>
  <link name="r_elbow_pitch_motor">
    <!--<collision>-->
      <!--<origin rpy="0 0 0" xyz="0 0 0"/>-->
      <!--<geometry>-->
        <!--<mesh filename="package://hdt_7dof_description/meshes/elbow_pitch_motor.stl"/>-->
      <!--</geometry>-->
    <!--</collision>-->
    <visual>
      <origin rpy="0 0 0" xyz="0 0 0.0"/>
      <geometry>
        <mesh filename="package://hdt_7dof_description/meshes/elbow_pitch_motor.stl"/>
      </geometry>
      <material name="r_grey"/>
    </visual>
    <inertial>
      <origin rpy="0 0 0" xyz="0 -0.02018105 0"/>
      <mass value="0.69896279"/>
      <inertia ixx="0.00094182" ixy="0.0" ixz="0.0" iyy="0.00032992" iyz="0.0" izz="0.00088116"/>
    </inertial>
  </link>
  <gazebo reference="r_elbow_pitch_motor">
    <material>Gazebo/Grey</material>
  </gazebo>
  <!-- forearm -->
  <joint name="r_elbow_roll" type="revolute">
    <hdt id="5.0" inertia="0.05" kmax="100" kmin="50"/>
    <axis xyz="0 -1 0"/>
    <limit effort="60.0" lower="-2.0944" upper="2.0944" velocity="2.0944"/>
    <origin rpy="0 0.0 0" xyz="0 -0.077 0"/>
    <parent link="r_elbow_pitch_motor"/>
    <child link="r_forearm"/>
    <dynamics damping="0.7" friction="0.0"/>
  </joint>
  <transmission name="r_tran5">
    <type>transmission_interface/SimpleTransmission</type>
    <joint name="r_elbow_roll">
			</joint>
    <actuator name="r_motor5">
      <hardwareInterface>EffortJointInterface</hardwareInterface>
      <mechanicalReduction>1</mechanicalReduction>
    </actuator>
  </transmission>
  <link name="r_forearm">
    <collision>
      <origin rpy="1.5707963267949 0 0" xyz="0 -0.04 0"/>
      <geometry>
        <cylinder radius="0.05" length="0.1" />
      </geometry>
    </collision>
    <visual>
      <origin rpy="0 0 0" xyz="0 0 0.0"/>
      <geometry>
        <mesh filename="package://hdt_7dof_description/meshes/forearm.stl"/>
      </geometry>
      <material name="r_maroon"/>
    </visual>
    <inertial>
      <origin rpy="0 0 0" xyz="0 -0.04487724 0"/>
      <mass value="1.00775488"/>
      <inertia ixx="0.00104342" ixy="0.0" ixz="0.0" iyy="0.00064952" iyz="0.0" izz="0.00104342"/>
    </inertial>
  </link>
  <gazebo reference="r_forearm">
    <material>Gazebo/Green</material>
  </gazebo>
  <joint name="r_forearm_fixed" type="fixed">
    <origin rpy="0 0 0" xyz="0 -0.0751 0"/>
    <parent link="r_forearm"/>
    <child link="r_wrist_pitch_bracket"/>
  </joint>
  <link name="r_wrist_pitch_bracket">
    <!--<collision>-->
      <!--<origin rpy="0 0 0" xyz="0 0 0"/>-->
      <!--<geometry>-->
        <!--<mesh filename="package://hdt_7dof_description/meshes/wrist_pitch_bracket.stl"/>-->
      <!--</geometry>-->
    <!--</collision>-->
    <visual>
      <origin rpy="0 0 0" xyz="0 0 0.0"/>
      <geometry>
        <mesh filename="package://hdt_7dof_description/meshes/wrist_pitch_bracket.stl"/>
      </geometry>
      <material name="r_black"/>
    </visual>
    <inertial>
      <origin rpy="0 0 0" xyz="0 -0.04112 0"/>
      <mass value="0.50058"/>
      <inertia ixx="0.000580228" ixy="0.0" ixz="0.0" iyy="0.000541503" iyz="0.0" izz="0.000750977"/>
    </inertial>
  </link>
  <gazebo reference="r_wrist_pitch_bracket">
    <material>Gazebo/Black</material>
  </gazebo>
  <!-- wrist pitch -->
  <joint name="r_wrist_pitch" type="revolute">
    <hdt id="6.0" inertia="0.05" kmax="100" kmin="50"/>
    <axis xyz="1 0 0"/>
    <limit effort="60.0" lower="-1.5708" upper="1.5708" velocity="2.0944"/>
    <origin rpy="0 0 0" xyz="0 -0.055 0"/>
    <parent link="r_wrist_pitch_bracket"/>
    <child link="r_wrist_motors"/>
    <dynamics damping="0.7" friction="0.0"/>
  </joint>
  <transmission name="r_tran6">
    <type>transmission_interface/SimpleTransmission</type>
    <joint name="r_wrist_pitch">
			</joint>
    <actuator name="r_motor6">
      <hardwareInterface>EffortJointInterface</hardwareInterface>
      <mechanicalReduction>1</mechanicalReduction>
    </actuator>
  </transmission>
  <link name="r_wrist_motors">
    <collision>
      <origin rpy="0 1.5707963267949 0" xyz="0 0 0"/>
      <geometry>
        <cylinder radius="0.05" length="0.08" />
      </geometry>
    </collision>
    <visual>
      <origin rpy="0 0 0" xyz="0 0 0.0"/>
      <geometry>
        <mesh filename="package://hdt_7dof_description/meshes/wrist_motors.stl"/>
      </geometry>
      <material name="r_grey"/>
    </visual>
    <inertial>
      <origin rpy="0 0 0" xyz="0 -0.03855 0"/>
      <mass value="0.99934"/>
      <inertia ixx="0.001905243" ixy="0.0" ixz="0.0" iyy="0.000474765" iyz="0.0" izz="0.001905243"/>
    </inertial>
  </link>
  <gazebo reference="r_wrist_motors">
    <material>Gazebo/Grey</material>
  </gazebo>
  <!-- wrist yaw -->
  <joint name="r_wrist_yaw" type="revolute">
    <hdt id="7.0" inertia="0.05" kmax="100" kmin="50"/>
    <axis xyz="0 0 1"/>
    <!-- <limit effort="60.0" lower="-1.5708" upper="1.5708" velocity="2.0944"/> -->
    <limit effort="60.0" lower="-1.5708" upper="0" velocity="2.0944"/>
    <origin rpy="0 0 0" xyz="0 -0.0741 0"/>
    <parent link="r_wrist_motors"/>
    <child link="r_wrist_yaw_bracket"/>
    <dynamics damping="0.7" friction="0.0"/>
  </joint>
  <transmission name="r_tran7">
    <type>transmission_interface/SimpleTransmission</type>
    <joint name="r_wrist_yaw">
			</joint>
    <actuator name="r_motor7">
      <hardwareInterface>EffortJointInterface</hardwareInterface>
      <mechanicalReduction>1</mechanicalReduction>
    </actuator>
  </transmission>
  <link name="r_wrist_yaw_bracket">
    <collision>
      <origin rpy="0 0 0" xyz="0 0 0"/>
      <geometry>
        <cylinder radius="0.05" length="0.08" />
      </geometry>
    </collision>
    <visual>
      <origin rpy="0 0 0" xyz="0 0 0.0"/>
      <geometry>
        <mesh filename="package://hdt_7dof_description/meshes/wrist_yaw_bracket.stl"/>
      </geometry>
      <material name="r_black"/>
    </visual>
    <inertial>
      <origin rpy="0 0 0" xyz="0 -0.01177 0"/>
      <mass value="0.47608"/>
      <inertia ixx="0.000705091" ixy="0.0" ixz="0.0" iyy="0.000537081" iyz="0.0" izz="0.000534342"/>
    </inertial>
  </link>
  <gazebo reference="r_wrist_yaw_bracket">
    <material>Gazebo/Black</material>
  </gazebo>
  <!-- palm -->
  <joint name="r_palm" type="fixed">
    <origin rpy="0 0 0" xyz="0 -0.1887 0"/>
    <parent link="r_wrist_yaw_bracket"/>
    <child link="r_hand"/>
  </joint>
  <link name="r_palm">
    <collision>
      <origin rpy="0 0 0" xyz="0 -0.068 0.004"/>
      <geometry>
        <box size="0.071 0.18 0.105"/>
      </geometry>
    </collision>
    <visual>
      <origin rpy="0 0 0" xyz="0 0 0.0"/>
      <geometry>
        <mesh filename="package://hdt_7dof_description/meshes/palm.stl"/>
      </geometry>
      <material name="r_black"/>
    </visual>
    <inertial>
      <origin rpy="0 0 0" xyz="0 -0.08326 -0.00539"/>
      <!-- <mass value="0.56756"/> -->
      <!-- <mass value="0.96756"/> -->
      <mass value="5.56756"/>
      <inertia ixx="0.001727803" ixy="0.000001205" ixz="0.0" iyy="0.000549457" iyz="-0.000101997" izz="0.001418031"/>
    </inertial>
  </link>
  <gazebo reference="r_palm">
    <material>Gazebo/Black</material>
  </gazebo>
  <!-- gripper frame -->
  <joint name="r_gripper_frame_joint" type="fixed">
    <origin rpy="0 0 -1.57079" xyz="0 0 0"/>
    <parent link="r_palm"/>
    <child link="r_gripper_frame"/>
  </joint>
  <link name="r_gripper_frame"/>
  <!-- Hacked in joint to match ViGIR frames -->
  <joint name="r_vigir_joint" type="fixed">
    <origin rpy="0 0 0" xyz="0 0.13 0"/>
    <parent link="r_hand"/>
    <child link="r_palm"/>
  </joint>
  <link name="r_hand"/>
  <!-- thumb base -->
  <joint name="r_thumb_roll" type="revolute">
    <hdt id="10.0" inertia="0.01" kmax="20" kmin="5"/>
    <axis xyz="0 -1 0"/>
    <limit effort="4.0" lower="-1.5708" upper="1.5708" velocity="4.1888"/>
    <origin rpy="0 0 0" xyz="0 -0.05039 0.01529"/>
    <parent link="r_palm"/>
    <child link="r_thumb_base"/>
    <dynamics damping="0.7" friction="0.0"/>
  </joint>
  <transmission name="r_tran10">
    <type>transmission_interface/SimpleTransmission</type>
    <joint name="r_thumb_roll">
            </joint>
    <actuator name="r_motor10">
      <hardwareInterface>EffortJointInterface</hardwareInterface>
      <mechanicalReduction>1</mechanicalReduction>
    </actuator>
  </transmission>
  <link name="r_thumb_base">
    <!--<collision>-->
      <!--<origin rpy="0 0 0" xyz="0 0 0"/>-->
      <!--<geometry>-->
        <!--<mesh filename="package://hdt_7dof_description/meshes/thumb_base.stl"/>-->
      <!--</geometry>-->
    <!--</collision>-->
    <visual>
      <origin rpy="0 0 0" xyz="0 0 0"/>
      <geometry>
        <mesh filename="package://hdt_7dof_description/meshes/thumb_base.stl"/>
      </geometry>
      <material name="r_grey"/>
    </visual>
    <inertial>
      <origin rpy="0 0 0" xyz="0 -0.02653 0.02207"/>
      <mass value="0.08562"/>
      <inertia ixx="0.0000315" ixy="0.0" ixz="0.0" iyy="0.000034299" iyz="0.0" izz="0.000022344"/>
    </inertial>
  </link>
  <gazebo reference="r_thumb_base">
    <material>Gazebo/Grey</material>
  </gazebo>
  <!-- thumb prox -->
  <joint name="r_thumb_pitch" type="revolute">
    <hdt id="11.0" inertia="0.01" kmax="20" kmin="5"/>
    <axis xyz="1 0 0"/>
    <limit effort="4.0" lower="-0.7854" upper="1.5708" velocity="4.1888"/>
    <origin rpy="0 0 0" xyz="0.00214 -0.030093 0.05703"/>
    <parent link="r_thumb_base"/>
    <child link="r_thumb_prox"/>
    <dynamics damping="0.7" friction="0.0"/>
  </joint>
  <transmission name="r_tran11">
    <type>transmission_interface/SimpleTransmission</type>
    <joint name="r_thumb_pitch">
            </joint>
    <actuator name="r_motor11">
      <hardwareInterface>EffortJointInterface</hardwareInterface>
      <mechanicalReduction>1</mechanicalReduction>
    </actuator>
  </transmission>
  <link name="r_thumb_prox">
    <collision>
      <origin rpy="0 0 0" xyz="0 0 0.054"/>
      <geometry>
        <cylinder radius="0.025" length="0.1" />
      </geometry>
    </collision>
    <visual>
      <origin rpy="0 0 0" xyz="0 0 0"/>
      <geometry>
        <mesh filename="package://hdt_7dof_description/meshes/thumb_prox.stl"/>
      </geometry>
      <material name="r_grey"/>
    </visual>
    <inertial>
      <mass value="0.025"/>
      <inertia ixx="0.0005" ixy="0.0" ixz="0.0" iyy="0.0005" iyz="0.0" izz="0.0005"/>
    </inertial>
  </link>
  <gazebo reference="r_thumb_prox">
    <material>Gazebo/Grey</material>
  </gazebo>
  <!-- thumb med -->
  <joint name="r_thumb_med" type="fixed">
    <origin rpy="0 0 0" xyz="0 0.00285 0.04341"/>
    <parent link="r_thumb_prox"/>
    <child link="r_thumb_med"/>
  </joint>
  <link name="r_thumb_med">
    <!--<collision>-->
      <!--<origin rpy="0 0 0" xyz="0 0 0"/>-->
      <!--<geometry>-->
        <!--<mesh filename="package://hdt_7dof_description/meshes/thumb_med.stl"/>-->
      <!--</geometry>-->
    <!--</collision>-->
    <visual>
      <origin rpy="0 0 0" xyz="0 0 0"/>
      <geometry>
        <mesh filename="package://hdt_7dof_description/meshes/thumb_med.stl"/>
      </geometry>
      <material name="r_black"/>
    </visual>
    <inertial>
      <origin rpy="0 0 0" xyz="0 -0.00353 0.01162"/>
      <mass value="0.0085"/>
      <inertia ixx="0.000001099" ixy="0.0" ixz="0.0" iyy="0.000001639" iyz="0.000000096" izz="0.000000981"/>
    </inertial>
  </link>
  <gazebo reference="r_thumb_med">
    <material>Gazebo/Black</material>
  </gazebo>
  <!-- thumb dist -->
  <joint name="r_thumb_dist" type="fixed">
    <origin rpy="0 0 0" xyz="0 -0.0009 0.02769"/>
    <parent link="r_thumb_med"/>
    <child link="r_thumb_dist"/>
  </joint>
  <link name="r_thumb_dist">
    <!--<collision>-->
      <!--<origin rpy="0 0 0" xyz="0 0 0"/>-->
      <!--<geometry>-->
        <!--<mesh filename="package://hdt_7dof_description/meshes/thumb_dist.stl"/>-->
      <!--</geometry>-->
    <!--</collision>-->
    <visual>
      <origin rpy="0 0 0" xyz="0 0 0"/>
      <geometry>
        <mesh filename="package://hdt_7dof_description/meshes/thumb_dist.stl"/>
      </geometry>
      <material name="r_grey"/>
    </visual>
    <inertial>
      <origin rpy="0 0 0" xyz="0 -0.00131 0.01323"/>
      <mass value="0.0092"/>
      <inertia ixx="0.00000066" ixy="0.0" ixz="0.0" iyy="0.000000837" iyz="0.0" izz="0.000000695"/>
    </inertial>
  </link>
  <gazebo reference="r_thumb_dist">
    <material>Gazebo/Grey</material>
  </gazebo>
  <!-- index prox -->
  <joint name="r_index_yaw" type="revolute">
    <hdt id="12.0" inertia="0.01" kmax="20" kmin="5"/>
    <axis xyz="0 0 1.0"/>
    <limit effort="4.0" lower="-0.7854" upper="1.5708" velocity="4.1888"/>
    <origin rpy="0 0.0 0" xyz="0 -0.163498 0.027"/>
    <parent link="r_palm"/>
    <child link="r_index_prox"/>
    <dynamics damping="0.7" friction="0.0"/>
  </joint>
  <transmission name="r_tran12">
    <type>transmission_interface/SimpleTransmission</type>
    <joint name="r_index_yaw">
            </joint>
    <actuator name="r_motor12">
      <hardwareInterface>EffortJointInterface</hardwareInterface>
      <mechanicalReduction>1</mechanicalReduction>
    </actuator>
  </transmission>
  <link name="r_index_prox">
    <collision>
      <origin rpy="-1.5707963267949 0 0" xyz="0 -0.043 0"/>
      <geometry>
        <cylinder radius="0.025" length="0.1" />
      </geometry>
    </collision>
    <visual>
      <origin rpy="0 0 0" xyz="0 0 0"/>
      <geometry>
        <mesh filename="package://hdt_7dof_description/meshes/finger_prox_right.stl"/>
      </geometry>
      <material name="r_grey"/>
    </visual>
    <inertial>
      <mass value="0.025"/>
      <inertia ixx="0.0005" ixy="0.0" ixz="0.0" iyy="0.0005" iyz="0.0" izz="0.0005"/>
    </inertial>
  </link>
  <gazebo reference="r_index_prox">
    <material>Gazebo/Grey</material>
  </gazebo>
  <!-- index med -->
  <joint name="r_index_med" type="fixed">
    <origin rpy="0 0 0" xyz="-0.00285 -0.04341 0"/>
    <parent link="r_index_prox"/>
    <child link="r_index_med"/>
  </joint>
  <link name="r_index_med">
    <!--<collision>-->
      <!--<origin rpy="0 0 0" xyz="0 0 0"/>-->
      <!--<geometry>-->
        <!--<mesh filename="package://hdt_7dof_description/meshes/finger_med_right.stl"/>-->
      <!--</geometry>-->
    <!--</collision>-->
    <visual>
      <origin rpy="0 0 0" xyz="0 0 0"/>
      <geometry>
        <mesh filename="package://hdt_7dof_description/meshes/finger_med_right.stl"/>
      </geometry>
      <material name="r_black"/>
    </visual>
    <inertial>
      <origin rpy="0 0 0" xyz="0.00353 -0.01162 0"/>
      <mass value="0.0085"/>
      <inertia ixx="0.000001639" ixy="0.000000096" ixz="0.0" iyy="0.000000981" iyz="0.0" izz="0.000001099"/>
    </inertial>
  </link>
  <gazebo reference="r_index_med">
    <material>Gazebo/Black</material>
  </gazebo>
  <!-- index dist -->
  <joint name="r_index_dist" type="fixed">
    <origin rpy="0 0 0" xyz="0.0009 -0.02769 0"/>
    <parent link="r_index_med"/>
    <child link="r_index_dist"/>
  </joint>
  <link name="r_index_dist">
    <!--<collision>-->
      <!--<origin rpy="0 0 0" xyz="0 0 0"/>-->
      <!--<geometry>-->
        <!--<mesh filename="package://hdt_7dof_description/meshes/finger_dist_right.stl"/>-->
      <!--</geometry>-->
    <!--</collision>-->
    <visual>
      <origin rpy="0 0 0" xyz="0 0 0"/>
      <geometry>
        <mesh filename="package://hdt_7dof_description/meshes/finger_dist_right.stl"/>
      </geometry>
      <material name="r_grey"/>
    </visual>
    <inertial>
      <origin rpy="0 0 0" xyz="0.00131 -0.01323 0"/>
      <mass value="0.0092"/>
      <inertia ixx="0.000000837" ixy="0.0" ixz="0.0" iyy="0.000000695" iyz="0.0" izz="0.00000066"/>
    </inertial>
  </link>
  <gazebo reference="r_index_dist">
    <material>Gazebo/Grey</material>
  </gazebo>
  <!-- ring prox -->
  <joint name="r_ring_yaw" type="revolute">
    <hdt id="13.0" inertia="0.01" kmax="20" kmin="5"/>
    <axis xyz="0 0 1.0"/>
    <limit effort="4.0" lower="-0.7854" upper="1.5708" velocity="4.1888"/>
    <origin rpy="0 0.0 0" xyz="0 -0.163498 -0.027"/>
    <parent link="r_palm"/>
    <child link="r_ring_prox"/>
    <dynamics damping="0.7" friction="0.0"/>
  </joint>
  <transmission name="r_tran13">
    <type>transmission_interface/SimpleTransmission</type>
    <joint name="r_ring_yaw">
            </joint>
    <actuator name="r_motor13">
      <hardwareInterface>EffortJointInterface</hardwareInterface>
      <mechanicalReduction>1</mechanicalReduction>
    </actuator>
  </transmission>
  <link name="r_ring_prox">
    <collision>
      <origin rpy="-1.5707963267949 0 0" xyz="0 -0.043 0"/>
      <geometry>
        <cylinder radius="0.025" length="0.1" />
      </geometry>
    </collision>
    <visual>
      <origin rpy="0 0 0" xyz="0 0 0"/>
      <geometry>
        <mesh filename="package://hdt_7dof_description/meshes/finger_prox_right.stl"/>
      </geometry>
      <material name="r_grey"/>
    </visual>
    <inertial>
      <mass value="0.025"/>
      <inertia ixx="0.0005" ixy="0.0" ixz="0.0" iyy="0.0005" iyz="0.0" izz="0.0005"/>
    </inertial>
  </link>
  <gazebo reference="r_ring_prox">
    <material>Gazebo/Grey</material>
  </gazebo>
  <!-- ring med -->
  <joint name="r_ring_med" type="fixed">
    <origin rpy="0 0 0" xyz="-0.00285 -0.04341 0"/>
    <parent link="r_ring_prox"/>
    <child link="r_ring_med"/>
  </joint>
  <link name="r_ring_med">
    <!--<collision>-->
      <!--<origin rpy="0 0 0" xyz="0 0 0"/>-->
      <!--<geometry>-->
        <!--<mesh filename="package://hdt_7dof_description/meshes/finger_med_right.stl"/>-->
      <!--</geometry>-->
    <!--</collision>-->
    <visual>
      <origin rpy="0 0 0" xyz="0 0 0"/>
      <geometry>
        <mesh filename="package://hdt_7dof_description/meshes/finger_med_right.stl"/>
      </geometry>
      <material name="r_black"/>
    </visual>
    <inertial>
      <origin rpy="0 0 0" xyz="0.00353 -0.01162 0"/>
      <mass value="0.0085"/>
      <inertia ixx="0.000001639" ixy="0.000000096" ixz="0.0" iyy="0.000000981" iyz="0.0" izz="0.000001099"/>
    </inertial>
  </link>
  <gazebo reference="r_ring_med">
    <material>Gazebo/Black</material>
  </gazebo>
  <!-- ring dist -->
  <joint name="r_ring_dist" type="fixed">
    <origin rpy="0 0 0" xyz="0.0009 -0.02769 0"/>
    <parent link="r_ring_med"/>
    <child link="r_ring_dist"/>
  </joint>
  <link name="r_ring_dist">
    <!--<collision>-->
      <!--<origin rpy="0 0 0" xyz="0 0 0"/>-->
      <!--<geometry>-->
        <!--<mesh filename="package://hdt_7dof_description/meshes/finger_dist_right.stl"/>-->
      <!--</geometry>-->
    <!--</collision>-->
    <visual>
      <origin rpy="0 0 0" xyz="0 0 0"/>
      <geometry>
        <mesh filename="package://hdt_7dof_description/meshes/finger_dist_right.stl"/>
      </geometry>
      <material name="r_grey"/>
    </visual>
    <inertial>
      <origin rpy="0 0 0" xyz="0.00131 -0.01323 0"/>
      <mass value="0.0092"/>
      <inertia ixx="0.000000837" ixy="0.0" ixz="0.0" iyy="0.000000695" iyz="0.0" izz="0.00000066"/>
    </inertial>
  </link>
  <gazebo reference="r_ring_dist">
    <material>Gazebo/Grey</material>
  </gazebo>
</robot>

